Workbook

Sheet Access Control
A1: ⬅ NAVIGATE:
A2: ElevateED — 🔒 AUTHORIZED ACCESS ONLY
A3: Talent Ready IT Program | Largo High School | Prince George's Community College
A4: Maryland Blueprint for Maryland's Future | CONFIDENTIAL — FERPA PROTECTED | Generated: February 13, 2026 03:35 PM
A6: ⚠️ THIS WORKBOOK CONTAINS FERPA-PROTECTED STUDENT DATA FOR 59 MINOR STUDENTS
A7: Unauthorized access, sharing, or distribution is a federal violation under 20 U.S.C. § 1232g and may result in criminal penalties.
A10: GOOGLE WORKSPACE / MICROSOFT 365 — AUTHENTICATION & SHARING SETUP
A12: SHAREPOINT / GOOGLE DRIVE ACCESS CONTROL
A13: Step 1: SharePoint Setup | B13: Create a SharePoint Team Site → 'Talent Ready ElevateED' → Set to Private | F13: Required
A14: Step 2: Upload Files | B14: Upload ALL ElevateED .xlsx files to the site document library | F14: Required
A15: Step 3: Add Authorized Users | B15: Site Settings → Permissions → Add the 6 authorized emails below | F15: Required
A16: Step 4: Google Login (if using Google Drive) | B16: Share folder with the 6 @pgcps.org emails below — Restricted access only | F16: Required
A17: Step 5: Verify No External Sharing | B17: Settings → Sharing → Ensure 'Only people in your org' is selected | F17: Required
A18: Step 6: Enable Audit Logging | B18: Compliance Center → Audit → Enable 'File and page activities' | F18: Required
A19: Step 7: Apply Sensitivity Label | B19: Microsoft 365 Compliance → Labels → Apply 'FERPA — Confidential' to all files | F19: Required
A20: Step 8: Test Access | B20: Log in as each authorized user → Verify they can see ONLY their permitted sheets | F20: Required
A23: 🛡️ AUTHORIZED USERS — SITE ADMINISTRATORS (Full Access)
A24: # | B24: Full Name | C24: Email Address (Google/M365 Login) | D24: Role | E24: Access Level | F24: Department | G24: FERPA Training | H24: Last Access | I24: Status | J24: Acknowledgment
A25: 1 | B25: Alphonsius Buma | C25: alphonsius.buma@pgcps.org | D25: Site Administrator | E25: Full Access — All Data, Config, User Mgmt | F25: PGCPS — Largo High School | G25: ✅ Complete (Aug 2025) | H25: February 13, 2026 03:35 PM | I25: ✅ ACTIVE | J25: Signed — On File
A26: 2 | B26: Carlton James | C26: carlton.james@pgcps.org | D26: Site Administrator | E26: Full Access — All Data, Config, User Mgmt | F26: PGCPS — Largo High School | G26: ✅ Complete (Aug 2025) | H26: February 13, 2026 03:35 PM | I26: ✅ ACTIVE | J26: Signed — On File
A29: 👁️ AUTHORIZED USERS — FULL DATA VIEWERS (Read-Only)
A30: # | B30: Full Name | C30: Email Address (Google/M365 Login) | D30: Role | E30: Access Level | F30: Department | G30: FERPA Training | H30: Last Access | I30: Status | J30: Acknowledgment
A31: 1 | B31: Keith Brice | C31: keith.brice@pgcps.org | D31: Authorized Viewer | E31: Full Data View — All Students, All Cohorts | F31: PGCPS — Largo High School | G31: ✅ Complete (Aug 2025) | H31: February 13, 2026 03:35 PM | I31: ✅ ACTIVE | J31: Signed — On File
A32: 2 | B32: Tomisha King | C32: tomisha.king@pgcps.org | D32: Site Administrator | E32: Full Access — All Data, Config, Status Changes | F32: PGCPS — Largo High School | G32: ✅ Complete (Aug 2025) | H32: February 13, 2026 03:35 PM | I32: ✅ ACTIVE | J32: Signed — On File
A33: 3 | B33: Albert Lewis | C33: albert.lewis@pgcps.org | D33: Authorized Viewer | E33: Full Data View — All Students, All Cohorts | F33: PGCPS — Largo High School | G33: ✅ Complete (Aug 2025) | H33: February 13, 2026 03:35 PM | I33: ✅ ACTIVE | J33: Signed — On File
A34: 4 | B34: Robyn Jones | C34: robyn.jones@pgcps.org | D34: Authorized Viewer | E34: Full Data View — All Students, All Cohorts | F34: PGCPS — Largo High School | G34: ✅ Complete (Aug 2025) | H34: February 13, 2026 03:35 PM | I34: ✅ ACTIVE | J34: Signed — On File
A37: 🚫 ALL OTHER USERS — ACCESS DENIED
A38: User Category | B38: Access Level | C38: Notes
A39: Anyone not listed above | B39: NO ACCESS | C39: Access attempt logged to audit trail
A40: Students | B40: NO ACCESS | C40: Students may not view their own raw data in this workbook
A41: Parents / Guardians | B41: NO ACCESS | C41: Parents receive Thursday email reports only — never direct access
A42: PGCC Instructors (not listed) | B42: NO ACCESS | C42: Instructors receive course-specific views only on request
A43: External Partners / Vendors | B43: NO ACCESS | C43: No third-party access without signed FERPA data-sharing agreement
A44: PGCPS IT Staff (not listed) | B44: NO ACCESS | C44: IT support uses admin role on request — logged and time-limited
A47: 📋 FERPA ACKNOWLEDGMENT — REQUIRED FOR ALL AUTHORIZED USERS
A48: By accessing this workbook, I acknowledge and agree to the following:
A50: 1. I have completed FERPA training and understand my obligations under 20 U.S.C. § 1232g.
A51: 2. I will access student data ONLY for legitimate educational purposes related to my assigned role.
A52: 3. I will NOT share, forward, copy, screenshot, or distribute any student data outside this system.
A53: 4. I will NOT store student data on personal devices, USB drives, or unauthorized cloud storage.
...

Sheet Student Master
A1: ⬅ NAVIGATE:
A2: ElevateED — STUDENT MASTER — 59 Active + 5 Alumni | Historical Trends Integrated
A3: Talent Ready IT Program | Largo High School | Prince George's Community College
A4: Maryland Blueprint for Maryland's Future | CONFIDENTIAL — FERPA PROTECTED | Generated: February 13, 2026 03:35 PM
A5: Running Document — All semesters | Prior history integrated | Alumni closed | February 13, 2026
A6: Student ID | B6: Last Name | C6: First Name | D6: Cohort | E6: Grade | F6: Status | G6: Course 1 | H6: C1 Sem | I6: C1 Avg | J6: Course 2 | K6: C2 Sem | L6: C2 Avg | M6: Course 3 | N6: C3 Sem | O6: C3 Avg | P6: Course 4 | Q6: C4 Sem | R6: C4 Avg | S6: Course 5 | T6: C5 Sem | U6: C5 Avg | V6: Course 6 | W6: C6 Sem | X6: C6 Avg | Y6: Course 7 | Z6: C7 Sem | AA6: C7 Avg | AB6: Overall Avg | AC6: GPA | AD6: Letter Grade | AE6: Status Flag | AF6: MTSS Tier | AG6: CCR Status | AH6: IEP | AI6: 504 | AJ6: Trend | AK6: Risk Score | AL6: Intervention | AM6: Last Updated
A7: TR-0001 | B7: CRICHTON III | C7: LEONARD | D7: 2026 | E7: 12 | F7: Active | G7: Calculus | H7: Fall 2025 | I7: 94 | J7: Psychology | K7: Fall 2025 | L7: 88.9 | M7: English | N7: Fall 2025 | O7: 85.5 | P7: Art | Q7: Fall 2025 | R7: 112.3 | S7: INT 2840 — System Analysis/Project Mgmt | T7: Spring 2026 | V7: INT 2310 — Windows Server Admin | W7: Spring 2026 | Y7: EGL 1340 — Composition II: Technical Writing | Z7: Spring 2026 | AB7: 95.2 | AC7: 3.81 | AD7: A | AE7: 🌟 Excelling | AF7: Tier 1 | AG7: ✅ Met | AH7: No | AI7: No | AJ7: → Stable | AK7: =IF(AB6="",0,IFERROR((100-AB6)*1.2+IF(AF6="Tier 3",20,IF(AF6="Tier 2",10,0))+IF(AH6="Yes",5,0),0)) -> 0 | AL7: None | AM7: 02/13/2026
A8: TR-0002 | B8: CROWELL | C8: KINGSTON | D8: 2026 | E8: 12 | F8: Active | G8: Calculus | H8: Fall 2025 | I8: 87.3 | J8: Psychology | K8: Fall 2025 | L8: 95.8 | M8: English | N8: Fall 2025 | O8: 88.2 | P8: Art | Q8: Fall 2025 | R8: 112.3 | S8: INT 2840 — System Analysis/Project Mgmt | T8: Spring 2026 | V8: INT 2310 — Windows Server Admin | W8: Spring 2026 | Y8: EGL 1340 — Composition II: Technical Writing | Z8: Spring 2026 | AB8: 95.9 | AC8: 3.84 | AD8: A | AE8: 🌟 Excelling | AF8: Tier 1 | AG8: ✅ Met | AH8: No | AI8: No | AJ8: → Stable | AK8: =IF(AB7="",0,IFERROR((100-AB7)*1.2+IF(AF7="Tier 3",20,IF(AF7="Tier 2",10,0))+IF(AH7="Yes",5,0),0)) -> 5.76 | AL8: None | AM8: 02/13/2026
A9: TR-0003 | B9: DAVIS | C9: GABRIEL | D9: 2026 | E9: 12 | F9: Active | G9: Calculus | H9: Fall 2025 | I9: 87.3 | J9: Psychology | K9: Fall 2025 | L9: 80.6 | M9: English | N9: Fall 2025 | O9: 92.9 | P9: Art | Q9: Fall 2025 | R9: 91.2 | S9: INT 2840 — System Analysis/Project Mgmt | T9: Spring 2026 | V9: INT 2310 — Windows Server Admin | W9: Spring 2026 | Y9: EGL 1340 — Composition II: Technical Writing | Z9: Spring 2026 | AB9: 88 | AC9: 3.52 | AD9: B | AE9: 🟢 On Track | AF9: Tier 1 | AG9: ✅ Met | AH9: No | AI9: No | AJ9: → Stable | AK9: =IF(AB8="",0,IFERROR((100-AB8)*1.2+IF(AF8="Tier 3",20,IF(AF8="Tier 2",10,0))+IF(AH8="Yes",5,0),0)) -> 4.92 | AL9: None | AM9: 02/13/2026
A10: TR-0004 | B10: FERSNER | C10: LAILAH | D10: 2026 | E10: 12 | F10: Active | G10: Calculus | H10: Fall 2025 | I10: 91.5 | J10: Psychology | K10: Fall 2025 | L10: 89.4 | M10: English | N10: Fall 2025 | O10: 95.8 | P10: Art | Q10: Fall 2025 | R10: 104 | S10: INT 2840 — System Analysis/Project Mgmt | T10: Spring 2026 | U10: 94.4 | V10: INT 2310 — Windows Server Admin | W10: Spring 2026 | X10: 97.15 | Y10: EGL 1340 — Composition II: Technical Writing | Z10: Spring 2026 | AA10: 95 | AB10: 95.3 | AC10: 3.81 | AD10: A | AE10: 🌟 Excelling | AF10: Tier 1 | AG10: ✅ Met | AH10: No | AI10: No | AJ10: → Stable | AK10: =IF(AB9="",0,IFERROR((100-AB9)*1.2+IF(AF9="Tier 3",20,IF(AF9="Tier 2",10,0))+IF(AH9="Yes",5,0),0)) -> 14.4 | AL10: None | AM10: 02/13/2026
A11: TR-0005 | B11: FORD | C11: JAMES | D11: 2026 | E11: 12 | F11: Active | G11: Calculus | H11: Fall 2025 | I11: 91.1 | J11: Psychology | K11: Fall 2025 | L11: 91.8 | M11: English | N11: Fall 2025 | O11: 81.3 | P11: Art | Q11: Fall 2025 | R11: 118 | S11: INT 2840 — System Analysis/Project Mgmt | T11: Spring 2026 | U11: 86 | V11: INT 2310 — Windows Server Admin | W11: Spring 2026 | X11: 98.14 | Y11: EGL 1340 — Composition II: Technical Writing | Z11: Spring 2026 | AA11: 88 | AB11: 93.5 | AC11: 3.74 | AD11: A | AE11: 🌟 Excelling | AF11: Tier 1 | AG11: ✅ Met | AH11: Yes | AI11: No | AJ11: → Stable | AK11: =IF(AB10="",0,IFERROR((100-AB10)*1.2+IF(AF10="Tier 3",20,IF(AF10="Tier 2",10,0))+IF(AH10="Yes",5,0),0)) -> 5.64 | AL11: None | AM11: 02/13/2026
A12: TR-0006 | B12: FORREST | C12: TYLEYL | D12: 2026 | E12: 12 | F12: Active | G12: Calculus | H12: Fall 2025 | I12: 95.7 | J12: Psychology | K12: Fall 2025 | L12: 96.7 | M12: English | N12: Fall 2025 | O12: 98.5 | P12: Art | Q12: Fall 2025 | R12: 116.8 | S12: INT 2840 — System Analysis/Project Mgmt | T12: Spring 2026 | V12: INT 2310 — Windows Server Admin | W12: Spring 2026 | Y12: EGL 1340 — Composition II: Technical Writing | Z12: Spring 2026 | AB12: 101.9 | AC12: 4 | AD12: A | AE12: 🌟 Excelling | AF12: Tier 1 | AG12: ✅ Met | AH12: No | AI12: No | AJ12: → Stable | AK12: =IF(AB11="",0,IFERROR((100-AB11)*1.2+IF(AF11="Tier 3",20,IF(AF11="Tier 2",10,0))+IF(AH11="Yes",5,0),0)) -> 12.8 | AL12: None | AM12: 02/13/2026
A13: TR-0007 | B13: JALLOH | C13: JENABU | D13: 2026 | E13: 12 | F13: Active | G13: Calculus | H13: Fall 2025 | I13: 98 | J13: Psychology | K13: Fall 2025 | L13: 87.8 | M13: English | N13: Fall 2025 | O13: 78.6 | P13: Art | Q13: Fall 2025 | R13: 93.9 | S13: INT 2840 — System Analysis/Project Mgmt | T13: Spring 2026 | V13: INT 2310 — Windows Server Admin | W13: Spring 2026 | Y13: EGL 1340 — Composition II: Technical Writing | Z13: Spring 2026 | AB13: 89.6 | AC13: 3.58 | AD13: B | AE13: 🟢 On Track | AF13: Tier 1 | AG13: ✅ Met | AH13: No | AI13: No | AJ13: → Stable | AK13: =IF(AB12="",0,IFERROR((100-AB12)*1.2+IF(AF12="Tier 3",20,IF(AF12="Tier 2",10,0))+IF(AH12="Yes",5,0),0)) -> -2.28 | AL13: None | AM13: 02/13/2026
A14: TR-0008 | B14: JOHNSON-BONILLA | C14: CHRISTOPHER | D14: 2026 | E14: 12 | F14: Active | G14: Calculus | H14: Fall 2025 | I14: 92.4 | J14: Psychology | K14: Fall 2025 | L14: 89.4 | M14: English | N14: Fall 2025 | O14: 94.7 | P14: Art | Q14: Fall 2025 | R14: 110.3 | S14: INT 2840 — System Analysis/Project Mgmt | T14: Spring 2026 | U14: 92.86 | V14: INT 2310 — Windows Server Admin | W14: Spring 2026 | X14: 98.31 | Y14: EGL 1340 — Composition II: Technical Writing | Z14: Spring 2026 | AA14: 83.5 | AB14: 94.5 | AC14: 3.78 | AD14: A | AE14: 🌟 Excelling | AF14: Tier 1 | AG14: ✅ Met | AH14: No | AI14: No | AJ14: → Stable | AK14: =IF(AB13="",0,IFERROR((100-AB13)*1.2+IF(AF13="Tier 3",20,IF(AF13="Tier 2",10,0))+IF(AH13="Yes",5,0),0)) -> 12.48 | AL14: None | AM14: 02/13/2026
A15: TR-0009 | B15: OLUBIYI | C15: OLUWANIFEMI | D15: 2026 | E15: 12 | F15: Active | G15: Calculus | H15: Fall 2025 | I15: 92.1 | J15: Psychology | K15: Fall 2025 | L15: 95.6 | M15: English | N15: Fall 2025 | O15: 94.5 | P15: Art | Q15: Fall 2025 | R15: 115 | S15: INT 2840 — System Analysis/Project Mgmt | T15: Spring 2026 | V15: INT 2310 — Windows Server Admin | W15: Spring 2026 | Y15: EGL 1340 — Composition II: Technical Writing | Z15: Spring 2026 | AB15: 99.3 | AC15: 3.97 | AD15: A | AE15: 🌟 Excelling | AF15: Tier 1 | AG15: ✅ Met | AH15: No | AI15: No | AJ15: → Stable | AK15: =IF(AB14="",0,IFERROR((100-AB14)*1.2+IF(AF14="Tier 3",20,IF(AF14="Tier 2",10,0))+IF(AH14="Yes",5,0),0)) -> 6.6 | AL15: None | AM15: 02/13/2026
A16: TR-0010 | B16: SANNI | C16: MOFEOLUWA | D16: 2026 | E16: 12 | F16: Active | G16: Calculus | H16: Fall 2025 | I16: 96.4 | J16: Psychology | K16: Fall 2025 | L16: 93.9 | M16: English | N16: Fall 2025 | O16: 96.4 | P16: Art | Q16: Fall 2025 | R16: 94.5 | S16: INT 2840 — System Analysis/Project Mgmt | T16: Spring 2026 | V16: INT 2310 — Windows Server Admin | W16: Spring 2026 | Y16: EGL 1340 — Composition II: Technical Writing | Z16: Spring 2026 | AB16: 95.3 | AC16: 3.81 | AD16: A | AE16: 🌟 Excelling | AF16: Tier 1 | AG16: ✅ Met | AH16: No | AI16: No | AJ16: → Stable | AK16: =IF(AB15="",0,IFERROR((100-AB15)*1.2+IF(AF15="Tier 3",20,IF(AF15="Tier 2",10,0))+IF(AH15="Yes",5,0),0)) -> 0.84 | AL16: None | AM16: 02/13/2026
A17: TR-0011 | B17: SCARLETT | C17: OLIVIA | D17: 2026 | E17: 12 | F17: Active | G17: Calculus | H17: Fall 2025 | I17: 95 | J17: Psychology | K17: Fall 2025 | L17: 76.7 | M17: English | N17: Fall 2025 | O17: 71.3 | P17: Art | Q17: Fall 2025 | R17: 112.9 | S17: INT 2840 — System Analysis/Project Mgmt | T17: Spring 2026 | U17: 84.07 | V17: INT 2310 — Windows Server Admin | W17: Spring 2026 | X17: 95.57 | Y17: EGL 1340 — Composition II: Technical Writing | Z17: Spring 2026 | AA17: 91 | AB17: 89.5 | AC17: 3.58 | AD17: B | AE17: 🟢 On Track | AF17: Tier 1 | AG17: ✅ Met | AH17: No | AI17: No | AJ17: → Stable | AK17: =IF(AB16="",0,IFERROR((100-AB16)*1.2+IF(AF16="Tier 3",20,IF(AF16="Tier 2",10,0))+IF(AH16="Yes",5,0),0)) -> 5.64 | AL17: None | AM17: 02/13/2026
A18: TR-0012 | B18: WALLACE | C18: JUSTIN | D18: 2026 | E18: 12 | F18: Active | G18: Calculus | H18: Fall 2025 | I18: 87.3 | J18: Psychology | K18: Fall 2025 | L18: 91.7 | M18: English | N18: Fall 2025 | O18: 95.8 | P18: Art | Q18: Fall 2025 | R18: 106.3 | S18: INT 2840 — System Analysis/Project Mgmt | T18: Spring 2026 | U18: 83.17 | V18: INT 2310 — Windows Server Admin | W18: Spring 2026 | X18: 86.45 | Y18: EGL 1340 — Composition II: Technical Writing | Z18: Spring 2026 | AA18: 82.5 | AB18: 90.5 | AC18: 3.62 | AD18: A | AE18: 🌟 Excelling | AF18: Tier 1 | AG18: ✅ Met | AH18: No | AI18: No | AJ18: → Stable | AK18: =IF(AB17="",0,IFERROR((100-AB17)*1.2+IF(AF17="Tier 3",20,IF(AF17="Tier 2",10,0))+IF(AH17="Yes",5,0),0)) -> 12.6 | AL18: None | AM18: 02/13/2026
A19: TR-0013 | B19: WILLIAMS | C19: CHLOE | D19: 2026 | E19: 12 | F19: Active | G19: Calculus | H19: Fall 2025 | I19: 94.8 | J19: Psychology | K19: Fall 2025 | L19: 90.6 | M19: English | N19: Fall 2025 | O19: 95.8 | P19: Art | Q19: Fall 2025 | R19: 111 | S19: INT 2840 — System Analysis/Project Mgmt | T19: Spring 2026 | U19: 95.19 | V19: INT 2310 — Windows Server Admin | W19: Spring 2026 | X19: 89.3 | Y19: EGL 1340 — Composition II: Technical Writing | Z19: Spring 2026 | AA19: 85 | AB19: 94.5 | AC19: 3.78 | AD19: A | AE19: 🌟 Excelling | AF19: Tier 1 | AG19: ✅ Met | AH19: Yes | AI19: No | AJ19: → Stable | AK19: =IF(AB18="",0,IFERROR((100-AB18)*1.2+IF(AF18="Tier 3",20,IF(AF18="Tier 2",10,0))+IF(AH18="Yes",5,0),0)) -> 11.4 | AL19: None | AM19: 02/13/2026
A20: TR-0014 | B20: WILBUR | C20: GABRIELLE | D20: 2026 | E20: 12 | F20: Active | G20: Calculus | H20: Fall 2025 | I20: 97.5 | J20: Psychology | K20: Fall 2025 | L20: 93.3 | M20: English | N20: Fall 2025 | O20: 97.5 | P20: Art | Q20: Fall 2025 | R20: 109.5 | S20: INT 2840 — System Analysis/Project Mgmt | T20: Spring 2026 | V20: INT 2310 — Windows Server Admin | W20: Spring 2026 | Y20: EGL 1340 — Composition II: Technical Writing | Z20: Spring 2026 | AB20: 99.5 | AC20: 3.98 | AD20: A | AE20: 🌟 Excelling | AF20: Tier 1 | AG20: ✅ Met | AH20: No | AI20: No | AJ20: → Stable | AK20: =IF(AB19="",0,IFERROR((100-AB19)*1.2+IF(AF19="Tier 3",20,IF(AF19="Tier 2",10,0))+IF(AH19="Yes",5,0),0)) -> 11.6 | AL20: None | AM20: 02/13/2026
A21: TR-0015 | B21: WINTERS | C21: AARON | D21: 2026 | E21: 12 | F21: Active | G21: Calculus | H21: Fall 2025 | I21: 89.9 | J21: Psychology | K21: Fall 2025 | L21: 92.8 | M21: English | N21: Fall 2025 | O21: 95.5 | P21: Art | Q21: Fall 2025 | R21: 107 | S21: INT 2840 — System Analysis/Project Mgmt | T21: Spring 2026 | U21: 87.3 | V21: INT 2310 — Windows Server Admin | W21: Spring 2026 | Y21: EGL 1340 — Composition II: Technical Writing | Z21: Spring 2026 | AA21: 85 | AB21: 92.9 | AC21: 3.72 | AD21: A | AE21: 🌟 Excelling | AF21: Tier 1 | AG21: ✅ Met | AH21: No | AI21: No | AJ21: → Stable | AK21: =IF(AB20="",0,IFERROR((100-AB20)*1.2+IF(AF20="Tier 3",20,IF(AF20="Tier 2",10,0))+IF(AH20="Yes",5,0),0)) -> 0.6 | AL21: None | AM21: 02/13/2026
A22: TR-0016 | B22: ZUBAIRU | C22: LATEEFAH | D22: 2026 | E22: 12 | F22: Active | G22: Calculus | H22: Fall 2025 | I22: 91.5 | J22: Psychology | K22: Fall 2025 | L22: 89.4 | M22: English | N22: Fall 2025 | O22: 95.8 | P22: Art | Q22: Fall 2025 | R22: 104 | S22: INT 2840 — System Analysis/Project Mgmt | T22: Spring 2026 | V22: INT 2310 — Windows Server Admin | W22: Spring 2026 | Y22: EGL 1340 — Composition II: Technical Writing | Z22: Spring 2026 | AB22: 95.2 | AC22: 3.81 | AD22: A | AE22: 🌟 Excelling | AF22: Tier 1 | AG22: ✅ Met | AH22: No | AI22: No | AJ22: → Stable | AK22: =IF(AB21="",0,IFERROR((100-AB21)*1.2+IF(AF21="Tier 3",20,IF(AF21="Tier 2",10,0))+IF(AH21="Yes",5,0),0)) -> 8.52 | AL22: None | AM22: 02/13/2026
A23: TR-0058 | B23: SCOTT | C23: SANAA | D23: 2026 | E23: 12 | F23: Active | G23: Calculus | H23: Fall 2025 | I23: 78.9 | J23: Psychology | K23: Fall 2025 | L23: 78.9 | M23: English | N23: Fall 2025 | O23: 78.9 | P23: Art | Q23: Fall 2025 | R23: 96.9 | S23: INT 2840 — System Analysis/Project Mgmt | T23: Spring 2026 | V23: INT 2310 — Windows Server Admin | W23: Spring 2026 | Y23: EGL 1340 — Composition II: Technical Writing | Z23: Spring 2026 | AB23: 83.4 | AC23: 3.34 | AD23: B | AE23: 🟢 On Track | AF23: Tier 1 | AG23: ✅ Met | AH23: No | AI23: No | AJ23: → Stable | AK23: =IF(AB22="",0,IFERROR((100-AB22)*1.2+IF(AF22="Tier 3",20,IF(AF22="Tier 2",10,0))+IF(AH22="Yes",5,0),0)) -> 5.76 | AL23: None | AM23: 02/13/2026
A24: TR-0017 | B24: BYFIELD | C24: KIMANI | D24: 2027 | E24: 11 | F24: Active | G24: BIO 1110 — Environmental Biology | H24: Fall 2025 | I24: 66.2 | J24: BIO 1120 — Environmental Biology Lab | K24: Fall 2025 | L24: 79.9 | M24: INT 1550 — Intro to Networks: Network+ Prep | N24: Fall 2025 | O24: 57.4 | AB24: 67.8 | AC24: 2.71 | AD24: D | AE24: 🟡 Watch | AF24: Tier 1/2 | AG24: ⚠️ Approaching | AH24: No | AI24: No | AJ24: → Stable | AK24: =IF(AB23="",0,IFERROR((100-AB23)*1.2+IF(AF23="Tier 3",20,IF(AF23="Tier 2",10,0))+IF(AH23="Yes",5,0),0)) -> 19.92 | AL24: None | AM24: 02/13/2026
A25: TR-0018 | B25: HODGE | C25: AMANI | D25: 2027 | E25: 11 | F25: Active | G25: BIO 1110 — Environmental Biology | H25: Fall 2025 | I25: 79.3 | J25: BIO 1120 — Environmental Biology Lab | K25: Fall 2025 | L25: 65 | M25: INT 1550 — Intro to Networks: Network+ Prep | N25: Fall 2025 | O25: 91.5 | AB25: 78.6 | AC25: 3.14 | AD25: C | AE25: 🟢 On Track | AF25: Tier 1 | AG25: ✅ Met | AH25: No | AI25: No | AJ25: → Stable | AK25: =IF(AB24="",0,IFERROR((100-AB24)*1.2+IF(AF24="Tier 3",20,IF(AF24="Tier 2",10,0))+IF(AH24="Yes",5,0),0)) -> 38.64 | AL25: None | AM25: 02/13/2026
A26: TR-0019 | B26: LAMBRIGHT | C26: KADYN | D26: 2027 | E26: 11 | F26: Active | G26: BIO 1110 — Environmental Biology | H26: Fall 2025 | I26: 86 | J26: BIO 1120 — Environmental Biology Lab | K26: Fall 2025 | L26: 65.1 | M26: INT 1550 — Intro to Networks: Network+ Prep | N26: Fall 2025 | O26: 64.2 | AB26: 71.8 | AC26: 2.87 | AD26: C | AE26: 🟡 Watch | AF26: Tier 1/2 | AG26: ⚠️ Approaching | AH26: No | AI26: No | AJ26: → Stable | AK26: =IF(AB25="",0,IFERROR((100-AB25)*1.2+IF(AF25="Tier 3",20,IF(AF25="Tier 2",10,0))+IF(AH25="Yes",5,0),0)) -> 25.68 | AL26: None | AM26: 02/13/2026
A27: TR-0020 | B27: NISBETH | C27: GRACE | D27: 2027 | E27: 11 | F27: Active | G27: BIO 1110 — Environmental Biology | H27: Fall 2025 | I27: 81.9 | J27: BIO 1120 — Environmental Biology Lab | K27: Fall 2025 | L27: 72.9 | M27: INT 1550 — Intro to Networks: Network+ Prep | N27: Fall 2025 | O27: 73.3 | AB27: 76 | AC27: 3.04 | AD27: C | AE27: 🟢 On Track | AF27: Tier 1 | AG27: ✅ Met | AH27: No | AI27: No | AJ27: → Stable | AK27: =IF(AB26="",0,IFERROR((100-AB26)*1.2+IF(AF26="Tier 3",20,IF(AF26="Tier 2",10,0))+IF(AH26="Yes",5,0),0)) -> 33.84 | AL27: None | AM27: 02/13/2026
A28: TR-0021 | B28: PAYTON | C28: JADEN | D28: 2027 | E28: 11 | F28: Active | G28: BIO 1110 — Environmental Biology | H28: Fall 2025 | I28: 66.4 | J28: BIO 1120 — Environmental Biology Lab | K28: Fall 2025 | L28: 89.6 | M28: INT 1550 — Intro to Networks: Network+ Prep | N28: Fall 2025 | O28: 78.9 | AB28: 78.3 | AC28: 3.13 | AD28: C | AE28: 🟢 On Track | AF28: Tier 1 | AG28: ✅ Met | AH28: No | AI28: No | AJ28: → Stable | AK28: =IF(AB27="",0,IFERROR((100-AB27)*1.2+IF(AF27="Tier 3",20,IF(AF27="Tier 2",10,0))+IF(AH27="Yes",5,0),0)) -> 28.8 | AL28: None | AM28: 02/13/2026
A29: TR-0022 | B29: WARD | C29: CANAAN | D29: 2027 | E29: 11 | F29: Active | G29: BIO 1110 — Environmental Biology | H29: Fall 2025 | I29: 83.2 | J29: BIO 1120 — Environmental Biology Lab | K29: Fall 2025 | L29: 93 | M29: INT 1550 — Intro to Networks: Network+ Prep | N29: Fall 2025 | O29: 80.5 | AB29: 85.6 | AC29: 3.42 | AD29: B | AE29: 🟢 On Track | AF29: Tier 1 | AG29: ✅ Met | AH29: No | AI29: No | AJ29: → Stable | AK29: =IF(AB28="",0,IFERROR((100-AB28)*1.2+IF(AF28="Tier 3",20,IF(AF28="Tier 2",10,0))+IF(AH28="Yes",5,0),0)) -> 26.04 | AL29: None | AM29: 02/13/2026
A30: TR-0023 | B30: AHETO | C30: EDWIN | D30: 2028 | E30: 10 | F30: Active | G30: COM 1010 — Speech Communication | H30: Fall 2025 | I30: 57 | J30: INT 1700 — Understanding Operating Systems | K30: Fall 2025 | L30: 98.5 | O30: 73.33 | R30: 82.27 | AB30: 77.8 | AC30: 3.11 | AD30: C | AE30: 🟢 On Track | AF30: Tier 1 | AG30: ✅ Met | AH30: No | AI30: No | AJ30: → Stable | AK30: =IF(AB29="",0,IFERROR((100-AB29)*1.2+IF(AF29="Tier 3",20,IF(AF29="Tier 2",10,0))+IF(AH29="Yes",5,0),0)) -> 17.28 | AL30: None | AM30: 02/13/2026
A31: TR-0024 | B31: ALI | C31: CALI | D31: 2028 | E31: 10 | F31: Active | G31: COM 1010 — Speech Communication | H31: Fall 2025 | I31: 87.4 | J31: INT 1700 — Understanding Operating Systems | K31: Fall 2025 | L31: 70.8 | O31: 60.95 | R31: 80.48 | AB31: 74.9 | AC31: 3 | AD31: C | AE31: 🟡 Watch | AF31: Tier 1/2 | AG31: ⚠️ Approaching | AH31: No | AI31: No | AJ31: → Stable | AK31: =IF(AB30="",0,IFERROR((100-AB30)*1.2+IF(AF30="Tier 3",20,IF(AF30="Tier 2",10,0))+IF(AH30="Yes",5,0),0)) -> 26.64 | AL31: None | AM31: 02/13/2026
A32: TR-0025 | B32: ANTHONY | C32: JELANI | D32: 2028 | E32: 10 | F32: Active | G32: COM 1010 — Speech Communication | H32: Fall 2025 | I32: 76 | J32: INT 1700 — Understanding Operating Systems | K32: Fall 2025 | L32: 89.3 | O32: 79.05 | R32: 67.83 | AB32: 78 | AC32: 3.12 | AD32: C | AE32: 🟢 On Track | AF32: Tier 1 | AG32: ✅ Met | AH32: No | AI32: No | AJ32: → Stable | AK32: =IF(AB31="",0,IFERROR((100-AB31)*1.2+IF(AF31="Tier 3",20,IF(AF31="Tier 2",10,0))+IF(AH31="Yes",5,0),0)) -> 30.12 | AL32: None | AM32: 02/13/2026
A33: TR-0026 | B33: EGUNJOBI | C33: OREOLUWA | D33: 2028 | E33: 10 | F33: Active | G33: COM 1010 — Speech Communication | H33: Fall 2025 | I33: 74.8 | J33: INT 1700 — Understanding Operating Systems | K33: Fall 2025 | L33: 72.8 | O33: 73.33 | R33: 68.21 | AB33: 72.3 | AC33: 2.89 | AD33: C | AE33: 🟡 Watch | AF33: Tier 1/2 | AG33: ⚠️ Approaching | AH33: No | AI33: No | AJ33: → Stable | AK33: =IF(AB32="",0,IFERROR((100-AB32)*1.2+IF(AF32="Tier 3",20,IF(AF32="Tier 2",10,0))+IF(AH32="Yes",5,0),0)) -> 26.4 | AL33: None | AM33: 02/13/2026
A34: TR-0027 | B34: ERHABOR | C34: ELAION | D34: 2028 | E34: 10 | F34: Active | G34: COM 1010 — Speech Communication | H34: Fall 2025 | I34: 61.2 | J34: INT 1700 — Understanding Operating Systems | K34: Fall 2025 | L34: 93.9 | AB34: 77.6 | AC34: 3.1 | AD34: C | AE34: 🟢 On Track | AF34: Tier 1 | AG34: ✅ Met | AH34: No | AI34: No | AJ34: → Stable | AK34: =IF(AB33="",0,IFERROR((100-AB33)*1.2+IF(AF33="Tier 3",20,IF(AF33="Tier 2",10,0))+IF(AH33="Yes",5,0),0)) -> 33.24 | AL34: None | AM34: 02/13/2026
A35: TR-0028 | B35: FERSNER | C35: KENNEDI | D35: 2028 | E35: 10 | F35: Active | G35: COM 1010 — Speech Communication | H35: Fall 2025 | I35: 72.6 | J35: INT 1700 — Understanding Operating Systems | K35: Fall 2025 | L35: 86.8 | O35: 73.33 | R35: 76.14 | AB35: 77.2 | AC35: 3.09 | AD35: C | AE35: 🟢 On Track | AF35: Tier 1 | AG35: ✅ Met | AH35: No | AI35: No | AJ35: → Stable | AK35: =IF(AB34="",0,IFERROR((100-AB34)*1.2+IF(AF34="Tier 3",20,IF(AF34="Tier 2",10,0))+IF(AH34="Yes",5,0),0)) -> 26.88 | AL35: None | AM35: 02/13/2026
A36: TR-0059 | B36: FORD | C36: CHASE | D36: 2028 | E36: 10 | F36: Active | G36: COM 1010 — Speech Communication | H36: Fall 2025 | I36: 47.2 | J36: INT 1700 — Understanding Operating Systems | K36: Fall 2025 | L36: 65 | AB36: 56.1 | AC36: 2.24 | AD36: F | AE36: 🔴 Not Progressing | AF36: Tier 3 | AG36: ❌ Below | AH36: No | AI36: No | AJ36: → Stable | AK36: =IF(AB35="",0,IFERROR((100-AB35)*1.2+IF(AF35="Tier 3",20,IF(AF35="Tier 2",10,0))+IF(AH35="Yes",5,0),0)) -> 27.36 | AL36: None | AM36: 02/13/2026
A37: TR-0029 | B37: FOSTER | C37: BRYANT | D37: 2028 | E37: 10 | F37: Active | G37: COM 1010 — Speech Communication | H37: Fall 2025 | I37: 87.1 | J37: INT 1700 — Understanding Operating Systems | K37: Fall 2025 | L37: 65 | O37: 77.14 | R37: 89.54 | AB37: 79.7 | AC37: 3.19 | AD37: C | AE37: 🟢 On Track | AF37: Tier 1 | AG37: ✅ Met | AH37: No | AI37: No | AJ37: → Stable | AK37: =IF(AB36="",0,IFERROR((100-AB36)*1.2+IF(AF36="Tier 3",20,IF(AF36="Tier 2",10,0))+IF(AH36="Yes",5,0),0)) -> 72.68 | AL37: None | AM37: 02/13/2026
A38: TR-0030 | B38: GOMEZ | C38: CHRISTIAN | D38: 2028 | E38: 10 | F38: Active | G38: COM 1010 — Speech Communication | H38: Fall 2025 | I38: 78.1 | J38: INT 1700 — Understanding Operating Systems | K38: Fall 2025 | L38: 89 | AB38: 83.5 | AC38: 3.34 | AD38: B | AE38: 🟢 On Track | AF38: Tier 1 | AG38: ✅ Met | AH38: No | AI38: No | AJ38: → Stable | AK38: =IF(AB37="",0,IFERROR((100-AB37)*1.2+IF(AF37="Tier 3",20,IF(AF37="Tier 2",10,0))+IF(AH37="Yes",5,0),0)) -> 24.36 | AL38: None | AM38: 02/13/2026
A39: TR-0031 | B39: JOHNSON | C39: LIAM | D39: 2028 | E39: 10 | F39: Active | G39: COM 1010 — Speech Communication | H39: Fall 2025 | I39: 91.3 | J39: INT 1700 — Understanding Operating Systems | K39: Fall 2025 | L39: 84.9 | O39: 90.91 | R39: 74.05 | AB39: 85.3 | AC39: 3.41 | AD39: B | AE39: 🟢 On Track | AF39: Tier 1 | AG39: ✅ Met | AH39: No | AI39: No | AJ39: → Stable | AK39: =IF(AB38="",0,IFERROR((100-AB38)*1.2+IF(AF38="Tier 3",20,IF(AF38="Tier 2",10,0))+IF(AH38="Yes",5,0),0)) -> 19.8 | AL39: None | AM39: 02/13/2026
A40: TR-0032 | B40: MONROE-HOOD | C40: JAHDAI | D40: 2028 | E40: 10 | F40: Active | G40: COM 1010 — Speech Communication | H40: Fall 2025 | I40: 58.3 | J40: INT 1700 — Understanding Operating Systems | K40: Fall 2025 | L40: 61.2 | O40: 88.57 | R40: 84.14 | AB40: 73.1 | AC40: 2.92 | AD40: C | AE40: 🟡 Watch | AF40: Tier 1/2 | AG40: ⚠️ Approaching | AH40: No | AI40: No | AJ40: → Stable | AK40: =IF(AB39="",0,IFERROR((100-AB39)*1.2+IF(AF39="Tier 3",20,IF(AF39="Tier 2",10,0))+IF(AH39="Yes",5,0),0)) -> 17.64 | AL40: None | AM40: 02/13/2026
...

Sheet Command Center
A1: ⬅ NAVIGATE:
A2: ElevateED — COMMAND CENTER
A3: Talent Ready IT Program | Largo High School | Prince George's Community College
A4: Maryland Blueprint for Maryland's Future | CONFIDENTIAL — FERPA PROTECTED | Generated: February 13, 2026 03:35 PM
A5: All Systems Integrated | Historical Trends Active | Alumni Tracked | February 13, 2026
A6: =COUNTA('Student Master'!A6:A64) -> 59 | D6: 64 | G6: 4 | J6: 10 | M6: 1200+
A7: ACTIVE STUDENTS | D7: TOTAL ENROLLED | G7: COHORTS | J7: ACTIVE COURSES | M7: LIVE FORMULAS
A9: COHORT PERFORMANCE MATRIX — ALL 4 COHORTS | FALL 2025 + SPRING 2026
A10: Cohort | B10: Grade | C10: Students | D10: Avg Grade | E10: On Track | F10: Watch | G10: At Risk | H10: Not Prog | I10: Honor Roll | J10: CCR Met % | K10: PGCC Courses
A11: Class of 2026 | B11: 12th Senior | C11: 17 | D11: =AVERAGEIF('Student Master'!D6:D64,2026,'Student Master'!AB6:AB64) -> 93.764706 | E11: =COUNTIFS('Student Master'!D6:D64,2026,'Student Master'!AE6:AE64,"On Track") -> 0 | F11: =COUNTIFS('Student Master'!D6:D64,2026,'Student Master'!AE6:AE64,"Watch") -> 0 | G11: =COUNTIFS('Student Master'!D6:D64,2026,'Student Master'!AE6:AE64,"At Risk") -> 0 | H11: =COUNTIFS('Student Master'!D6:D64,2026,'Student Master'!AE6:AE64,"Not Progressing") -> 0 | I11: =COUNTIFS('Student Master'!D6:D64,2026,'Student Master'!AB6:AB64,">="&90) -> 13 | J11: =IFERROR(COUNTIFS('Student Master'!D6:D64,2026,'Student Master'!AG6:AG64,"✅ Met")/COUNTIF('Student Master'!D6:D64,2026),0) -> 1 | K11: Calculus, Psychology, English, Art + INT 2840, INT 2310, EGL 1340
A12: Class of 2027 | B12: 11th Junior | C12: 6 | D12: =AVERAGEIF('Student Master'!D6:D64,2027,'Student Master'!AB6:AB64) -> 76.35 | E12: =COUNTIFS('Student Master'!D6:D64,2027,'Student Master'!AE6:AE64,"On Track") -> 0 | F12: =COUNTIFS('Student Master'!D6:D64,2027,'Student Master'!AE6:AE64,"Watch") -> 0 | G12: =COUNTIFS('Student Master'!D6:D64,2027,'Student Master'!AE6:AE64,"At Risk") -> 0 | H12: =COUNTIFS('Student Master'!D6:D64,2027,'Student Master'!AE6:AE64,"Not Progressing") -> 0 | I12: =COUNTIFS('Student Master'!D6:D64,2027,'Student Master'!AB6:AB64,">="&90) -> 0 | J12: =IFERROR(COUNTIFS('Student Master'!D6:D64,2027,'Student Master'!AG6:AG64,"✅ Met")/COUNTIF('Student Master'!D6:D64,2027),0) -> 0.66666667 | K12: BIO 1110, BIO 1120, INT 1550
A13: Class of 2028 | B13: 10th Sophomore | C13: 20 | D13: =AVERAGEIF('Student Master'!D6:D64,2028,'Student Master'!AB6:AB64) -> 78.115 | E13: =COUNTIFS('Student Master'!D6:D64,2028,'Student Master'!AE6:AE64,"On Track") -> 0 | F13: =COUNTIFS('Student Master'!D6:D64,2028,'Student Master'!AE6:AE64,"Watch") -> 0 | G13: =COUNTIFS('Student Master'!D6:D64,2028,'Student Master'!AE6:AE64,"At Risk") -> 0 | H13: =COUNTIFS('Student Master'!D6:D64,2028,'Student Master'!AE6:AE64,"Not Progressing") -> 0 | I13: =COUNTIFS('Student Master'!D6:D64,2028,'Student Master'!AB6:AB64,">="&90) -> 1 | J13: =IFERROR(COUNTIFS('Student Master'!D6:D64,2028,'Student Master'!AG6:AG64,"✅ Met")/COUNTIF('Student Master'!D6:D64,2028),0) -> 0.7 | K13: COM 1010, INT 1700
A14: Class of 2029 | B14: 9th Freshman | C14: 16 | D14: =AVERAGEIF('Student Master'!D6:D64,2029,'Student Master'!AB6:AB64) -> 78.88 | E14: =COUNTIFS('Student Master'!D6:D64,2029,'Student Master'!AE6:AE64,"On Track") -> 0 | F14: =COUNTIFS('Student Master'!D6:D64,2029,'Student Master'!AE6:AE64,"Watch") -> 0 | G14: =COUNTIFS('Student Master'!D6:D64,2029,'Student Master'!AE6:AE64,"At Risk") -> 0 | H14: =COUNTIFS('Student Master'!D6:D64,2029,'Student Master'!AE6:AE64,"Not Progressing") -> 0 | I14: =COUNTIFS('Student Master'!D6:D64,2029,'Student Master'!AB6:AB64,">="&90) -> 2 | J14: =IFERROR(COUNTIFS('Student Master'!D6:D64,2029,'Student Master'!AG6:AG64,"✅ Met")/COUNTIF('Student Master'!D6:D64,2029),0) -> 0.6 | K14: INT 1010
A15: Class of 2025 🎓 | B15: Graduated | C15: 5 | D15: 87.7 | E15: 5 | F15: 0 | G15: 0 | H15: 0 | I15: 4 | J15: 1 | K15: 🎓 Accounts closed
A17: MTSS TIER DISTRIBUTION
A18: Tier | B18: Description | C18: Range | D18: Count | E18: % of Total | F18: Action
A19: Tier 1 | B19: On Track | C19: ≥ 75% | D19: =COUNTIF('Student Master'!AF6:AF64,"Tier 1") -> 44 | E19: =IFERROR(D18/COUNTA('Student Master'!AF6:AF64),0) -> 0 | F19: Standard monitoring
A20: Tier 1/2 | B20: Watch | C20: 65–74% | D20: =COUNTIF('Student Master'!AF6:AF64,"Tier 1/2") -> 12 | E20: =IFERROR(D19/COUNTA('Student Master'!AF6:AF64),0) -> 0.74576271 | F20: Increased monitoring
A21: Tier 2 | B21: At Risk | C21: 60–64% | D21: =COUNTIF('Student Master'!AF6:AF64,"Tier 2") -> 1 | E21: =IFERROR(D20/COUNTA('Student Master'!AF6:AF64),0) -> 0.20338983 | F21: SIT meeting, tutoring
A22: Tier 3 | B22: Not Progressing | C22: < 60% | D22: =COUNTIF('Student Master'!AF6:AF64,"Tier 3") -> 1 | E22: =IFERROR(D21/COUNTA('Student Master'!AF6:AF64),0) -> 0.016949153 | F22: Immediate intervention
A25: ⚠ EARLY WARNING ALERTS — Immediate Attention Required
A26: Priority | B26: Student ID | C26: Name | D26: Cohort | E26: Course | F26: Current Avg | G26: Status | H26: Days | I26: Assigned To | J26: Action
A27: 🔴 CRITICAL | B27: TR-0059 | C27: FORD, CHASE | D27: 2028 | E27: COM 1010 | F27: 47.2 | G27: Not Progressing | H27: 14 | I27: C. James | J27: Daily check-in + parent contact
A28: 🔴 CRITICAL | B28: TR-0017 | C28: BYFIELD, KIMANI | D28: 2027 | E28: INT 1550 | F28: 57.4 | G28: Not Progressing | H28: 10 | I28: C. James | J28: SIT meeting 2/18
A29: 🔴 CRITICAL | B29: TR-0023 | C29: AHETO, EDWIN | D29: 2028 | E29: COM 1010 | F29: 57 | G29: Not Progressing | H29: 12 | I29: C. James | J29: Peer tutoring assigned
A30: 🔴 CRITICAL | B30: TR-0032 | C30: MONROE-HOOD, JAHDAI | D30: 2028 | E30: COM 1010 | F30: 58.3 | G30: Not Progressing | H30: 8 | I30: C. James | J30: Weekly progress contract
A31: 🟠 HIGH | B31: TR-0042 | C31: AKINSANYA, TIARAOLUWA | D31: 2029 | E31: INT 1010 | F31: 60.9 | G31: At Risk | H31: 5 | I31: C. James | J31: Study plan created
A32: 🟠 HIGH | B32: TR-0027 | C32: ERHABOR, ELAION | D32: 2028 | E32: COM 1010 | F32: 61.2 | G32: At Risk | H32: 7 | I32: C. James | J32: Monitor weekly
A33: 🟡 WATCH | B33: TR-0019 | C33: LAMBRIGHT, KADYN | D33: 2027 | E33: INT 1550 | F33: 64.2 | G33: Watch | H33: 3 | I33: C. James | J33: Check-in conversation
A34: 🟡 WATCH | B34: TR-0044 | C34: BELCHER, MALACHI | D34: 2029 | E34: INT 1010 | F34: 65.3 | G34: Watch | H34: 2 | I34: C. James | J34: Attendance check

Sheet 📍 Navigation Hub
A1: ⬅ QUICK JUMP: | B1: ⚡ Command | C1: 👥 2026 | D1: 👥 2027 | E1: 👥 2028 | F1: 👥 2029 | G1: 📊 Master
A2: ElevateED — 📍 NAVIGATION HUB
A3: Talent Ready IT Program | Largo High School | Prince George's Community College
A4: Click any sheet name to jump directly | February 13, 2026
A6: 59 | B6: 5 | C6: 64 | D6: 4 | E6: 10
A7: Active | B7: Alumni | C7: Total | D7: Cohorts | E7: Courses
A9: 🔐 SECURITY
A10: 1 | B10: Access Control | C10: RBAC, FERPA, status change permissions | D10: ✅
A12: 📊 CORE DATA
A13: 2 | B13: Student Master | C13: 59 active + 5 alumni, 39 cols | D13: ✅
A14: 3 | B14: Command Center | C14: KPIs, cohort matrix, early warnings | D14: ✅
A15: 4 | B15: 📍 Navigation Hub | C15: ← YOU ARE HERE | D15: ✅
A16: 5 | B16: Academic Calendar | C16: PGCC + PGCPS synced | D16: ✅
A18: 📈 GRADES (Current First, Prior Hidden)
A19: 6 | B19: Cohort 2026 — Grades | C19: 17 seniors | Spring 2026 current, Fall 2025 grouped | D19: ✅
A20: 7 | B20: Cohort 2027 — Grades | C20: 6 juniors | Spring 2026 current, 3 prior semesters grouped | D20: ✅
A21: 8 | B21: Cohort 2028 — Grades | C21: 20 sophs | Spring 2026 current, Fall+Spring prior grouped | D21: ✅
A22: 9 | B22: Cohort 2029 — Grades | C22: 16 freshmen | Spring 2026 current, Fall 2025 grouped | D22: ✅
A24: 📊 HISTORICAL TRENDS
A25: 10 | B25: Alumni — Class of 2025 | C25: 5 grads, weekly detail, closed | D25: 🔧
A26: 11 | B26: History — Cohort 2026 | C26: Fall 2025 baseline + trends | D26: 🔧
A27: 12 | B27: History — Cohort 2027 | C27: 3 prior semesters | D27: 🔧
A28: 13 | B28: History — Cohort 2028 | C28: 2 prior semesters | D28: 🔧
A29: 14 | B29: History — Cohort 2029 | C29: Fall 2025 baseline | D29: 🔧
A30: 15 | B30: Program Trend Summary | C30: All cohorts side-by-side | D30: 🔧
A31: 16 | B31: Semester Grade Archive | C31: Flat file, every grade ever | D31: 🔧
A33: 🔍 ANALYTICS
A34: 17 | B34: Predictive Analytics | C34: 6-factor risk scores | D34: ✅
A35: 18 | B35: Executive Dashboard | C35: WoW/MoM/QoQ | D35: ✅
A36: 19 | B36: Grade Velocity | C36: Week-over-week Δ | D36: ✅
A37: 20 | B37: Course Performance | C37: 10 courses | D37: ✅
A38: 21 | B38: Longitudinal Analytics | C38: Year-over-year | D38: ✅
A40: 🛡️ COMPLIANCE
A41: 22 | B41: MTSS Tracker | C41: Tier tracking | D41: ✅
A42: 23 | B42: Intervention Planner | C42: SIT plans | D42: ✅
A43: 24 | B43: Compliance Center | C43: FERPA audit | D43: ✅
A44: 25 | B44: Blueprint Metrics | C44: Pillar 3+4 | D44: ✅
A45: 26 | B45: IEP Monitoring | C45: 2 students, 8 goals | D45: ✅
A47: 👪 PARENT & STUDENT
A48: 27 | B48: Parent Engagement | C48: 59 families | D48: ✅
...

Sheet Academic Calendar
A1: ⬅ NAVIGATE:
A2: ElevateED — ACADEMIC CALENDAR — PGCC + PGCPS SYNCHRONIZED
A3: Talent Ready IT Program | Largo High School | Prince George's Community College
A4: Maryland Blueprint for Maryland's Future | CONFIDENTIAL — FERPA PROTECTED | February 13, 2026 05:39 PM
A5: Fall 2025 + Spring 2026 | Week numbers aligned to PGCC 15-week Terms | Grades due every Thursday by 2:00 PM
A6: Date | B6: Day | C6: Event | D6: Source | E6: Type | F6: PGCC Week | G6: ElevateED Week | H6: Impact on Grades | I6: Action Required | J6: Notes
A7: FALL 2025 SEMESTER
A8: 2025-08-18 | B8: Mon | C8: PGCC Fall 2025 classes BEGIN (Term 1, 15-week) | D8: PGCC | E8: 🟢 Semester Start | F8: W1 | G8: W1 | H8: Normal entry | I8: Enter grades
A9: 2025-09-01 | B9: Mon | C9: Labor Day — COLLEGE & PGCPS CLOSED | D9: Both | E9: 🔴 Holiday | F9: — | G9: — | H9: No grades this week | I9: Skip week
A10: 2025-10-13 | B10: Mon | C10: Columbus Day — PGCPS Closed / PGCC Open | D10: PGCPS | E10: 🟡 Split | F10: W9 | G10: W9 | H10: Normal entry | I10: Enter grades
A11: 2025-11-03 | B11: Mon | C11: PGCPS End of Q1 — Early Dismissal | D11: PGCPS | E11: 🟡 Grading Day | F11: W12 | G11: W12 | H11: Normal entry | I11: Enter grades
A12: 2025-11-11 | B12: Tue | C12: Veterans Day — PGCPS Closed / PGCC Open | D12: PGCPS | E12: 🟡 Split | F12: W13 | G12: W13 | H12: Normal entry | I12: Enter grades
A13: 2025-11-24 | B13: Mon | C13: THANKSGIVING BREAK BEGINS | D13: Both | E13: 🔴 Break | F13: — | G13: — | H13: No grades this week | I13: Skip week
A14: 2025-12-01 | B14: Mon | C14: Classes resume from Thanksgiving | D14: Both | E14: 🟢 Resume | F14: W15 | G14: W15 | H14: Normal entry | I14: Enter grades
A15: 2025-12-08 | B15: Mon | C15: PGCC Finals BEGIN | D15: PGCC | E15: 🔴 Finals | F15: W16 | G15: W16 | H15: Final grades | I15: Enter grades
A16: 2025-12-12 | B16: Fri | C16: PGCC Finals END — Fall 2025 Complete | D16: PGCC | E16: 🔴 Finals End | F16: W16 | G16: W16 | H16: Final grades | I16: Enter grades
A17: 2025-12-22 | B17: Mon | C17: PGCPS Winter Break begins | D17: PGCPS | E17: 🔴 Break | F17: — | G17: — | H17: No grades | I17: —
A18: SPRING 2026 SEMESTER
A19: 2026-01-20 | B19: Tue | C19: PGCC Spring 2026 classes BEGIN (Term 1, 15-week) | D19: PGCC | E19: 🟢 Semester Start | F19: W1 | G19: W1 | H19: Normal entry | I19: Enter grades
A20: 2026-01-19 | B20: Mon | C20: MLK Jr. Day — COLLEGE & PGCPS CLOSED | D20: Both | E20: 🔴 Holiday | F20: — | G20: — | H20: No grades this week | I20: Skip week
A21: 2026-01-26 | B21: Mon | C21: PGCPS End of Q2 — Early Dismissal | D21: PGCPS | E21: 🟡 Grading Day | F21: W1 | G21: W1 | H21: Normal entry | I21: Enter grades
A22: 2026-02-01 | B22: Sun | C22: Fall 2026 nursing petitioning deadline | D22: PGCC | E22: 📋 Admin | F22: W2 | G22: W2 | H22: Normal entry | I22: Enter grades
A23: 2026-02-06 | B23: Fri | C23: Last day credit/audit change (Term 1) | D23: PGCC | E23: 📋 Admin | F23: W3 | G23: W3 | H23: Normal entry | I23: Enter grades
A24: 2026-02-13 | B24: Fri | C24: PGCPS Teacher Planning — Early Dismissal | D24: PGCPS | E24: 🟡 Half Day | F24: W4 | G24: W4 | H24: Normal entry | I24: Enter grades
A25: 2026-02-16 | B25: Mon | C25: Presidents Day — COLLEGE & PGCPS CLOSED | D25: Both | E25: 🔴 Holiday | F25: — | G25: — | H25: No grades this week | I25: Skip week
A26: 2026-02-17 | B26: Tue | C26: PGCPS: First Day of Ramadan | D26: PGCPS | E26: 📋 Note | F26: W4 | G26: W4 | H26: Normal entry | I26: Enter grades
A27: 2026-03-05 | B27: Thu | C27: Last day withdraw Term 2 (7-week accel) | D27: PGCC | E27: 📋 Admin | F27: W7 | G27: W7 | H27: Normal entry | I27: Enter grades
A28: 2026-03-09 | B28: Mon | C28: PGCC SPRING BREAK BEGINS | D28: PGCC | E28: 🔴 Break | F28: W7 | G28: W7 | H28: Normal entry | I28: Enter grades
A29: 2026-03-16 | B29: Mon | C29: PGCC classes resume / Term 4 begins | D29: PGCC | E29: 🟢 Resume | F29: W8 | G29: W8 | H29: Normal entry | I29: Enter grades
A30: 2026-03-18 | B30: Wed | C30: PGCPS: Last Day of Ramadan | D30: PGCPS | E30: 📋 Note | F30: W9 | G30: W9 | H30: Normal entry | I30: Enter grades
A31: 2026-03-20 | B31: Fri | C31: PGCPS: Eid al-Fitr / Prof Dev — Closed | D31: PGCPS | E31: 🔴 Holiday | F31: W9 | G31: W9 | H31: Normal entry | I31: Enter grades
A32: 2026-03-27
A33: 2026-03-30 | B33: Mon | C33: PGCPS Spring Break begins / Fall reg starts | D33: Both | E33: 🔴 Break | F33: W10 | G33: W10 | H33: Normal entry | I33: Enter grades
A34: 2026-04-03 | B34: Fri | C34: PGCPS Easter — Offices Closed | D34: PGCPS | E34: 🔴 Holiday | F34: W11 | G34: W11 | H34: Normal entry | I34: Enter grades
A35: 2026-04-06 | B35: Mon | C35: PGCPS resumes from Spring Break | D35: PGCPS | E35: 🟢 Resume | F35: W11 | G35: W11 | H35: Normal entry | I35: Enter grades
A36: 2026-04-22 | B36: Wed | C36: PGCPS Teacher Planning — Early Dismissal | D36: PGCPS | E36: 🟡 Half Day | F36: W14 | G36: W14 | H36: Normal entry | I36: Enter grades
A37: 2026-05-04 | B37: Mon | C37: PGCC Last day of classes (Term 1, 15-week) | D37: PGCC | E37: ⚠️ Last Class | F37: W15 | G37: W15 | H37: Normal entry | I37: Enter grades
A38: 2026-05-05 | B38: Tue | C38: PGCC Finals BEGIN | D38: PGCC | E38: 🔴 Finals | F38: W15 | G38: W15 | H38: Normal entry | I38: Enter grades
A39: 2026-05-08 | B39: Fri | C39: PGCPS Last Day for HS Seniors | D39: PGCPS | E39: 🎓 Senior Last Day | F39: W16 | G39: W16 | H39: Normal entry | I39: Enter grades
A40: 2026-05-11 | B40: Mon | C40: PGCC Finals END | D40: PGCC | E40: 🔴 Finals End | F40: W16 | G40: W16 | H40: Normal entry | I40: Enter grades
...

Sheet Cohort 2026 — Grades
A1: ⬅ NAVIGATE: | B1: 📍 Nav Hub | C1: ⚡ Command | D1: 👥 2026 | E1: 👥 2027 | F1: 👥 2028 | G1: 👥 2029
A2: ElevateED — COHORT 2026 — 12th Grade Seniors | 17 Students | Weekly Grade Tracker
A3: Talent Ready IT Program | Largo High School | Prince George's Community College
A4: Maryland Blueprint for Maryland's Future | CONFIDENTIAL — FERPA PROTECTED | February 13, 2026
A5: Current: Spring 2026 (INT 2840, INT 2310, EGL 1340) | Prior: Fall 2025 (BIO 1110, BIO 1120) | Grades due every Thursday by 2:00 PM | PGCC Calendar synced | * = Holiday Thu, due day before
A7: TR-0001 — CRICHTON III, LEONARD
A8: Spring 2026 (Current)
A9: Course | B9: W1 1/22 | C9: W2 1/29 | D9: W3 2/05 | E9: W4 2/12 | F9: W5 2/19 | G9: W6 2/26 | H9: W7 3/05 | I9: W8 3/19 | J9: W9 3/26 | K9: W10 4/01* | L9: W11 4/09 | M9: W12 4/16 | N9: W13 4/23 | O9: W14 4/30 | P9: W15 5/07 | Q9: CUM
A10: INT 2840 — System Analysis/Project Mgmt
A11: INT 2310 — Windows Server Admin
A12: EGL 1340 — Composition II: Technical Writing
A14: Fall 2025 (12th Grade — BIO/BIO Lab)
A15: Course | B15: W1 8/21 | C15: W2 8/28 | D15: W3 9/04 | E15: W4 9/11 | F15: W5 9/18 | G15: W6 9/25 | H15: W7 10/02 | I15: W8 10/09 | J15: W9 10/16 | K15: W10 10/23 | L15: W11 10/30 | M15: W12 11/06 | N15: W13 11/13 | O15: W14 11/20 | P15: W15 12/04 | Q15: CUM
A16: BIO 1110 — Environmental Biology | P16: 94 | Q16: 94
A17: BIO 1120 — Environmental Biology Lab | P17: 88.9 | Q17: 88.9
A20: TR-0002 — CROWELL, KINGSTON
A21: Spring 2026 (Current)
A22: Course | B22: W1 1/22 | C22: W2 1/29 | D22: W3 2/05 | E22: W4 2/12 | F22: W5 2/19 | G22: W6 2/26 | H22: W7 3/05 | I22: W8 3/19 | J22: W9 3/26 | K22: W10 4/01* | L22: W11 4/09 | M22: W12 4/16 | N22: W13 4/23 | O22: W14 4/30 | P22: W15 5/07 | Q22: CUM
A23: INT 2840 — System Analysis/Project Mgmt
A24: INT 2310 — Windows Server Admin
A25: EGL 1340 — Composition II: Technical Writing
A27: Fall 2025 (12th Grade — BIO/BIO Lab)
A28: Course | B28: W1 8/21 | C28: W2 8/28 | D28: W3 9/04 | E28: W4 9/11 | F28: W5 9/18 | G28: W6 9/25 | H28: W7 10/02 | I28: W8 10/09 | J28: W9 10/16 | K28: W10 10/23 | L28: W11 10/30 | M28: W12 11/06 | N28: W13 11/13 | O28: W14 11/20 | P28: W15 12/04 | Q28: CUM
A29: BIO 1110 — Environmental Biology | P29: 87.25 | Q29: 87.25
A30: BIO 1120 — Environmental Biology Lab | P30: 95.83 | Q30: 95.83
A33: TR-0003 — DAVIS, GABRIEL
A34: Spring 2026 (Current)
A35: Course | B35: W1 1/22 | C35: W2 1/29 | D35: W3 2/05 | E35: W4 2/12 | F35: W5 2/19 | G35: W6 2/26 | H35: W7 3/05 | I35: W8 3/19 | J35: W9 3/26 | K35: W10 4/01* | L35: W11 4/09 | M35: W12 4/16 | N35: W13 4/23 | O35: W14 4/30 | P35: W15 5/07 | Q35: CUM
A36: INT 2840 — System Analysis/Project Mgmt
A37: INT 2310 — Windows Server Admin
A38: EGL 1340 — Composition II: Technical Writing
A40: Fall 2025 (12th Grade — BIO/BIO Lab)
A41: Course | B41: W1 8/21 | C41: W2 8/28 | D41: W3 9/04 | E41: W4 9/11 | F41: W5 9/18 | G41: W6 9/25 | H41: W7 10/02 | I41: W8 10/09 | J41: W9 10/16 | K41: W10 10/23 | L41: W11 10/30 | M41: W12 11/06 | N41: W13 11/13 | O41: W14 11/20 | P41: W15 12/04 | Q41: CUM
A42: BIO 1110 — Environmental Biology | P42: 87.33 | Q42: 87.33
A43: BIO 1120 — Environmental Biology Lab | P43: 80.56 | Q43: 80.56
A46: TR-0004 — FERSNER, LAILAH
A47: Spring 2026 (Current)
A48: Course | B48: W1 1/22 | C48: W2 1/29 | D48: W3 2/05 | E48: W4 2/12 | F48: W5 2/19 | G48: W6 2/26 | H48: W7 3/05 | I48: W8 3/19 | J48: W9 3/26 | K48: W10 4/01* | L48: W11 4/09 | M48: W12 4/16 | N48: W13 4/23 | O48: W14 4/30 | P48: W15 5/07 | Q48: CUM
A49: INT 2840 — System Analysis/Project Mgmt | H49: 94.4% | Q49: 94.4%
A50: INT 2310 — Windows Server Admin | G50: 97.2% | Q50: 97.2%
...

Sheet Cohort 2027 — Grades
A1: ⬅ NAVIGATE: | B1: 📍 Nav Hub | C1: ⚡ Command | D1: 👥 2026 | E1: 👥 2027 | F1: 👥 2028 | G1: 👥 2029
A2: ElevateED — COHORT 2027 — 11th Grade Juniors | 6 Students | Weekly Grade Tracker
A3: Talent Ready IT Program | Largo High School | Prince George's Community College
A4: Maryland Blueprint for Maryland's Future | CONFIDENTIAL — FERPA PROTECTED | February 13, 2026
A5: Current: Spring 2026 (INT 1620, INT 1540, INT 2600) | Prior: Fall 2025, Spring 2025, Fall 2024 | Grades due every Thursday by 2:00 PM | PGCC Calendar synced | * = Holiday Thu, due day before
A7: TR-0017 — BYFIELD, KIMANI
A8: Spring 2026 (Current)
A9: Course | B9: W1 1/22 | C9: W2 1/29 | D9: W3 2/05 | E9: W4 2/12 | F9: W5 2/19 | G9: W6 2/26 | H9: W7 3/05 | I9: W8 3/19 | J9: W9 3/26 | K9: W10 4/01* | L9: W11 4/09 | M9: W12 4/16 | N9: W13 4/23 | O9: W14 4/30 | P9: W15 5/07 | Q9: CUM
A10: INT 1620 — Intro to Server Admin | Q10: 78.29
A11: INT 1540 — Intro to Cybersecurity | Q11: 100
A12: INT 2600 — Security Fundamentals | Q12: 86
A14: Fall 2025 (11th Grade)
A15: Course | B15: W1 8/21 | C15: W2 8/28 | D15: W3 9/04 | E15: W4 9/11 | F15: W5 9/18 | G15: W6 9/25 | H15: W7 10/02 | I15: W8 10/09 | J15: W9 10/16 | K15: W10 10/23 | L15: W11 10/30 | M15: W12 11/06 | N15: W13 11/13 | O15: W14 11/20 | P15: W15 12/04 | Q15: CUM
A16: INT 1550 — Intro to Networks: Network+ Prep | P16: 77.6 | Q16: 57.4%
A17: BIO 1110 — Environmental Biology | P17: 87.17 | Q17: 66.2%
A18: BIO 1120 — Env Biology Lab | P18: 64.12 | Q18: 79.9%
A20: Spring 2025 (10th Grade)
A21: Course | B21: W1 1/23 | C21: W2 1/30 | D21: W3 2/06 | E21: W4 2/13 | F21: W5 2/20 | G21: W6 2/27 | H21: W7 3/06 | I21: W8 3/20 | J21: W9 3/27 | K21: W10 4/03 | L21: W11 4/10 | M21: W12 4/17 | N21: W13 4/24 | O21: W14 5/01 | P21: W15 5/08 | Q21: CUM
A22: NTR 1010 — Nutrition | P22: 56.43 | Q22: 56.43
A23: SOC 1010 — Intro to Sociology | P23: 106.67 | Q23: 106.67
A25: Fall 2024 (10th Grade)
A26: Course | B26: W1 8/22 | C26: W2 8/29 | D26: W3 9/05 | E26: W4 9/12 | F26: W5 9/19 | G26: W6 9/26 | H26: W7 10/03 | I26: W8 10/10 | J26: W9 10/17 | K26: W10 10/24 | L26: W11 10/31 | M26: W12 11/07 | N26: W13 11/14 | O26: W14 11/21 | P26: W15 12/05 | Q26: CUM
A27: INT 1700 — Understanding OS | P27: 73.82 | Q27: 73.82
A28: COM 1010 — Speech Communication | P28: 90.86 | Q28: 90.86
A31: TR-0018 — HODGE, AMANI
A32: Spring 2026 (Current)
A33: Course | B33: W1 1/22 | C33: W2 1/29 | D33: W3 2/05 | E33: W4 2/12 | F33: W5 2/19 | G33: W6 2/26 | H33: W7 3/05 | I33: W8 3/19 | J33: W9 3/26 | K33: W10 4/01* | L33: W11 4/09 | M33: W12 4/16 | N33: W13 4/23 | O33: W14 4/30 | P33: W15 5/07 | Q33: CUM
A34: INT 1620 — Intro to Server Admin | Q34: 95
A35: INT 2600 — Security Fundamentals | Q35: 43.61
A37: Fall 2025 (11th Grade)
A38: Course | B38: W1 8/21 | C38: W2 8/28 | D38: W3 9/04 | E38: W4 9/11 | F38: W5 9/18 | G38: W6 9/25 | H38: W7 10/02 | I38: W8 10/09 | J38: W9 10/16 | K38: W10 10/23 | L38: W11 10/30 | M38: W12 11/06 | N38: W13 11/13 | O38: W14 11/20 | P38: W15 12/04 | Q38: CUM
A39: INT 1550 — Intro to Networks: Network+ Prep | P39: 79.1 | Q39: 91.5%
A40: BIO 1110 — Environmental Biology | P40: 83.51 | Q40: 79.3%
A41: BIO 1120 — Env Biology Lab | P41: 74.9 | Q41: 65.0%
A43: Spring 2025 (10th Grade)
A44: Course | B44: W1 1/23 | C44: W2 1/30 | D44: W3 2/06 | E44: W4 2/13 | F44: W5 2/20 | G44: W6 2/27 | H44: W7 3/06 | I44: W8 3/20 | J44: W9 3/27 | K44: W10 4/03 | L44: W11 4/10 | M44: W12 4/17 | N44: W13 4/24 | O44: W14 5/01 | P44: W15 5/08 | Q44: CUM
A45: NTR 1010 — Nutrition | P45: 67.25 | Q45: 67.25
A46: SOC 1010 — Intro to Sociology | P46: 91.43 | Q46: 91.43
A48: Fall 2024 (10th Grade)
A49: Course | B49: W1 8/22 | C49: W2 8/29 | D49: W3 9/05 | E49: W4 9/12 | F49: W5 9/19 | G49: W6 9/26 | H49: W7 10/03 | I49: W8 10/10 | J49: W9 10/17 | K49: W10 10/24 | L49: W11 10/31 | M49: W12 11/07 | N49: W13 11/14 | O49: W14 11/21 | P49: W15 12/05 | Q49: CUM
...

Sheet Cohort 2028 — Grades
A1: ⬅ NAVIGATE: | B1: 📍 Nav Hub | C1: ⚡ Command | D1: 👥 2026 | E1: 👥 2027 | F1: 👥 2028 | G1: 👥 2029
A2: ElevateED — COHORT 2028 — 10th Grade Sophomores | 20 Students | Weekly Grade Tracker
A3: Talent Ready IT Program | Largo High School | Prince George's Community College
A4: Maryland Blueprint for Maryland's Future | CONFIDENTIAL — FERPA PROTECTED | February 13, 2026
A5: Current: Spring 2026 (COM 1010, INT 1700) | Prior: Fall 2025, Spring 2025 | Grades due every Thursday by 2:00 PM | PGCC Calendar synced | * = Holiday Thu, due day before
A7: TR-0023 — AHETO, EDWIN | R7: Hick - C / Team Sports D
A8: Spring 2026 (Current)
A9: Course | B9: W1 1/22 | C9: W2 1/29 | D9: W3 2/05 | E9: W4 2/12 | F9: W5 2/19 | G9: W6 2/26 | H9: W7 3/05 | I9: W8 3/19 | J9: W9 3/26 | K9: W10 4/01* | L9: W11 4/09 | M9: W12 4/16 | N9: W13 4/23 | O9: W14 4/30 | P9: W15 5/07 | Q9: CUM
A10: SOC 1010 — Introduction to Sociology | J10: 73.3% | Q10: 73.3%
A11: NTR 1010 — Introduction to Nutrition | J11: 82.3% | Q11: 82.3%
A13: Fall 2025 (10th Grade)
A14: Course | B14: W1 8/21 | C14: W2 8/28 | D14: W3 9/04 | E14: W4 9/11 | F14: W5 9/18 | G14: W6 9/25 | H14: W7 10/02 | I14: W8 10/09 | J14: W9 10/16 | K14: W10 10/23 | L14: W11 10/30 | M14: W12 11/06 | N14: W13 11/13 | O14: W14 11/20 | P14: W15 12/04 | Q14: CUM
A15: COM 1010 — Speech Communication | P15: 57 | Q15: 57
A16: INT 1700 — Understanding OS | P16: 98.5 | Q16: 98.5
A18: Spring 2025 (9th Grade)
A19: Course | B19: W1 1/23 | C19: W2 1/30 | D19: W3 2/06 | E19: W4 2/13 | F19: W5 2/20 | G19: W6 2/27 | H19: W7 3/06 | I19: W8 3/20 | J19: W9 3/27 | K19: W10 4/03 | L19: W11 4/10 | M19: W12 4/17 | N19: W13 4/24 | O19: W14 5/01 | P19: W15 5/08 | Q19: CUM
A20: INT 1010 — Intro to Info Tech | P20: 82.5 | Q20: 82.5
A23: TR-0024 — ALI, CALI | R23: English E Local State - D
A24: Spring 2026 (Current)
A25: Course | B25: W1 1/22 | C25: W2 1/29 | D25: W3 2/05 | E25: W4 2/12 | F25: W5 2/19 | G25: W6 2/26 | H25: W7 3/05 | I25: W8 3/19 | J25: W9 3/26 | K25: W10 4/01* | L25: W11 4/09 | M25: W12 4/16 | N25: W13 4/23 | O25: W14 4/30 | P25: W15 5/07 | Q25: CUM
A26: SOC 1010 — Introduction to Sociology | J26: 61.0% | Q26: 61.0%
A27: NTR 1010 — Introduction to Nutrition | J27: 80.5% | Q27: 80.5%
A29: Fall 2025 (10th Grade)
A30: Course | B30: W1 8/21 | C30: W2 8/28 | D30: W3 9/04 | E30: W4 9/11 | F30: W5 9/18 | G30: W6 9/25 | H30: W7 10/02 | I30: W8 10/09 | J30: W9 10/16 | K30: W10 10/23 | L30: W11 10/30 | M30: W12 11/06 | N30: W13 11/13 | O30: W14 11/20 | P30: W15 12/04 | Q30: CUM
A31: COM 1010 — Speech Communication | P31: 87.38 | Q31: 87.38
A32: INT 1700 — Understanding OS | P32: 82 | Q32: 82
A34: Spring 2025 (9th Grade)
A35: Course | B35: W1 1/23 | C35: W2 1/30 | D35: W3 2/06 | E35: W4 2/13 | F35: W5 2/20 | G35: W6 2/27 | H35: W7 3/06 | I35: W8 3/20 | J35: W9 3/27 | K35: W10 4/03 | L35: W11 4/10 | M35: W12 4/17 | N35: W13 4/24 | O35: W14 5/01 | P35: W15 5/08 | Q35: CUM
A36: INT 1010 — Intro to Info Tech | P36: 88 | Q36: 88
A39: TR-0025 — ANTHONY, JELANI | R39: Advance Design Application. / Teacher add zero for assignment not graded.
A40: Spring 2026 (Current) | R40: Spanish D
A41: Course | B41: W1 1/22 | C41: W2 1/29 | D41: W3 2/05 | E41: W4 2/12 | F41: W5 2/19 | G41: W6 2/26 | H41: W7 3/05 | I41: W8 3/19 | J41: W9 3/26 | K41: W10 4/01* | L41: W11 4/09 | M41: W12 4/16 | N41: W13 4/23 | O41: W14 4/30 | P41: W15 5/07 | Q41: CUM
A42: SOC 1010 — Introduction to Sociology | J42: 79.0% | Q42: 79.0%
A43: NTR 1010 — Introduction to Nutrition | J43: 67.8% | Q43: 67.8%
A45: Fall 2025 (10th Grade)
A46: Course | B46: W1 8/21 | C46: W2 8/28 | D46: W3 9/04 | E46: W4 9/11 | F46: W5 9/18 | G46: W6 9/25 | H46: W7 10/02 | I46: W8 10/09 | J46: W9 10/16 | K46: W10 10/23 | L46: W11 10/30 | M46: W12 11/06 | N46: W13 11/13 | O46: W14 11/20 | P46: W15 12/04 | Q46: CUM
A47: COM 1010 — Speech Communication | P47: 76 | Q47: 76
A48: INT 1700 — Understanding OS | P48: 75 | Q48: 75
A50: Spring 2025 (9th Grade)
A51: Course | B51: W1 1/23 | C51: W2 1/30 | D51: W3 2/06 | E51: W4 2/13 | F51: W5 2/20 | G51: W6 2/27 | H51: W7 3/06 | I51: W8 3/20 | J51: W9 3/27 | K51: W10 4/03 | L51: W11 4/10 | M51: W12 4/17 | N51: W13 4/24 | O51: W14 5/01 | P51: W15 5/08 | Q51: CUM
...

Sheet Cohort 2029 — Grades
A1: ⬅ NAVIGATE: | B1: 📍 Nav Hub | C1: ⚡ Command | D1: 👥 2026 | E1: 👥 2027 | F1: 👥 2028 | G1: 👥 2029
A2: ElevateED — COHORT 2029 — 9th Grade Freshmen | 16 Students | Weekly Grade Tracker
A3: Talent Ready IT Program | Largo High School | Prince George's Community College
A4: Maryland Blueprint for Maryland's Future | CONFIDENTIAL — FERPA PROTECTED | February 13, 2026
A5: Current: Spring 2026 (INT 1111 + PAS 1000 for select students) | Prior: Fall 2025 (INT 1010) | Grades due every Thursday by 2:00 PM | PGCC Calendar synced | * = Holiday Thu, due day before
A7: TR-0042 — AKINSANYA, TIARAOLUWA
A8: Spring 2026 (Current)
A9: Course | B9: W1 1/22 | C9: W2 1/29 | D9: W3 2/05 | E9: W4 2/12 | F9: W5 2/19 | G9: W6 2/26 | H9: W7 3/05 | I9: W8 3/19 | J9: W9 3/26 | K9: W10 4/01* | L9: W11 4/09 | M9: W12 4/16 | N9: W13 4/23 | O9: W14 4/30 | P9: W15 5/07 | Q9: CUM
A10: INT 1111 — Introduction to IT II | Q10: 99.17
A12: Fall 2025 (First Semester)
A13: Course | B13: W1 8/21 | C13: W2 8/28 | D13: W3 9/04 | E13: W4 9/11 | F13: W5 9/18 | G13: W6 9/25 | H13: W7 10/02 | I13: W8 10/09 | J13: W9 10/16 | K13: W10 10/23 | L13: W11 10/30 | M13: W12 11/06 | N13: W13 11/13 | O13: W14 11/20 | P13: W15 12/04 | Q13: CUM
A14: INT 1010 — Intro to Information Technology | P14: 85.22 | Q14: 60.9%
A17: TR-0043 — ATKINS, PEYTON
A18: Spring 2026 (Current)
A19: Course | B19: W1 1/22 | C19: W2 1/29 | D19: W3 2/05 | E19: W4 2/12 | F19: W5 2/19 | G19: W6 2/26 | H19: W7 3/05 | I19: W8 3/19 | J19: W9 3/26 | K19: W10 4/01* | L19: W11 4/09 | M19: W12 4/16 | N19: W13 4/23 | O19: W14 4/30 | P19: W15 5/07 | Q19: CUM
A20: INT 1111 — Introduction to IT II | Q20: 95
A21: PAS 1000 — Personal & Academic Success | Q21: 12.25
A23: Fall 2025 (First Semester)
A24: Course | B24: W1 8/21 | C24: W2 8/28 | D24: W3 9/04 | E24: W4 9/11 | F24: W5 9/18 | G24: W6 9/25 | H24: W7 10/02 | I24: W8 10/09 | J24: W9 10/16 | K24: W10 10/23 | L24: W11 10/30 | M24: W12 11/06 | N24: W13 11/13 | O24: W14 11/20 | P24: W15 12/04 | Q24: CUM
A25: INT 1010 — Intro to Information Technology | P25: 62.61 | Q25: 89.3%
A28: TR-0044 — BELCHER, MALACHI
A29: Spring 2026 (Current)
A30: Course | B30: W1 1/22 | C30: W2 1/29 | D30: W3 2/05 | E30: W4 2/12 | F30: W5 2/19 | G30: W6 2/26 | H30: W7 3/05 | I30: W8 3/19 | J30: W9 3/26 | K30: W10 4/01* | L30: W11 4/09 | M30: W12 4/16 | N30: W13 4/23 | O30: W14 4/30 | P30: W15 5/07 | Q30: CUM
A31: INT 1111 — Introduction to IT II | Q31: 100
A33: Fall 2025 (First Semester)
A34: Course | B34: W1 8/21 | C34: W2 8/28 | D34: W3 9/04 | E34: W4 9/11 | F34: W5 9/18 | G34: W6 9/25 | H34: W7 10/02 | I34: W8 10/09 | J34: W9 10/16 | K34: W10 10/23 | L34: W11 10/30 | M34: W12 11/06 | N34: W13 11/13 | O34: W14 11/20 | P34: W15 12/04 | Q34: CUM
A35: INT 1010 — Intro to Information Technology | P35: 77.68 | Q35: 65.3%
A38: TR-0045 — DUMAS, ADDISON
A39: Spring 2026 (Current)
A40: Course | B40: W1 1/22 | C40: W2 1/29 | D40: W3 2/05 | E40: W4 2/12 | F40: W5 2/19 | G40: W6 2/26 | H40: W7 3/05 | I40: W8 3/19 | J40: W9 3/26 | K40: W10 4/01* | L40: W11 4/09 | M40: W12 4/16 | N40: W13 4/23 | O40: W14 4/30 | P40: W15 5/07 | Q40: CUM
A41: INT 1111 — Introduction to IT II | Q41: 95.27
A43: Fall 2025 (First Semester)
A44: Course | B44: W1 8/21 | C44: W2 8/28 | D44: W3 9/04 | E44: W4 9/11 | F44: W5 9/18 | G44: W6 9/25 | H44: W7 10/02 | I44: W8 10/09 | J44: W9 10/16 | K44: W10 10/23 | L44: W11 10/30 | M44: W12 11/06 | N44: W13 11/13 | O44: W14 11/20 | P44: W15 12/04 | Q44: CUM
A45: INT 1010 — Intro to Information Technology | P45: 85.78 | Q45: 78.8%
A48: TR-0046 — HARRISON, MACKENZIE
A49: Spring 2026 (Current)
A50: Course | B50: W1 1/22 | C50: W2 1/29 | D50: W3 2/05 | E50: W4 2/12 | F50: W5 2/19 | G50: W6 2/26 | H50: W7 3/05 | I50: W8 3/19 | J50: W9 3/26 | K50: W10 4/01* | L50: W11 4/09 | M50: W12 4/16 | N50: W13 4/23 | O50: W14 4/30 | P50: W15 5/07 | Q50: CUM
A51: INT 1111 — Introduction to IT II | Q51: 96.47
A53: Fall 2025 (First Semester)
A54: Course | B54: W1 8/21 | C54: W2 8/28 | D54: W3 9/04 | E54: W4 9/11 | F54: W5 9/18 | G54: W6 9/25 | H54: W7 10/02 | I54: W8 10/09 | J54: W9 10/16 | K54: W10 10/23 | L54: W11 10/30 | M54: W12 11/06 | N54: W13 11/13 | O54: W14 11/20 | P54: W15 12/04 | Q54: CUM
...

Sheet Predictive Analytics
A1: ⬅ NAVIGATE:
A2: ElevateED — PREDICTIVE ANALYTICS ENGINE
A3: Talent Ready IT Program | Largo High School | Prince George's Community College
A4: Maryland Blueprint for Maryland's Future | CONFIDENTIAL — FERPA PROTECTED | Generated: February 13, 2026 03:41 PM
A5: 6-Factor Risk Algorithm | Trajectory Modeling | Early Warning System | Updated: February 13, 2026 03:41 PM
A6: Student ID | B6: Name | C6: Cohort | D6: Current Avg | E6: 4wk Trend | F6: Attendance | G6: Assignments | H6: IEP Factor | I6: Engagement | J6: RISK SCORE | K6: RISK LEVEL | L6: Days to At-Risk | M6: Predicted EOY | N6: Confidence
A7: TR-0001 | B7: CRICHTON III, LEONARD | C7: 2026 | D7: 0.952 | E7: 3.8 | F7: 0.95 | G7: 0.92 | H7: 0.93 | I7: 0.9 | J7: 5.8 | K7: LOW | L7: N/A | M7: 0.97 | N7: 0.88
A8: TR-0002 | B8: CROWELL, KINGSTON | C8: 2026 | D8: 0.959 | E8: 4.2 | F8: 0.97 | G8: 0.94 | H8: 0.93 | I8: 0.91 | J8: 4.6 | K8: LOW | L8: N/A | M8: 0.98 | N8: 0.9
A9: TR-0003 | B9: DAVIS, GABRIEL | C9: 2026 | D9: 0.88 | E9: 1.5 | F9: 0.88 | G9: 0.85 | H9: 0.93 | I9: 0.82 | J9: 12.3 | K9: LOW | L9: N/A | M9: 0.91 | N9: 0.82
A10: TR-0004 | B10: FERSNER, LAILAH | C10: 2026 | D10: 0.952 | E10: 2.8 | F10: 0.93 | G10: 0.95 | H10: 0.93 | I10: 0.94 | J10: 5 | K10: LOW | L10: N/A | M10: 0.97 | N10: 0.89
A11: TR-0005 | B11: FORD, JAMES | C11: 2026 | D11: 0.956 | E11: 1.2 | F11: 0.9 | G11: 0.88 | H11: 0.75 | I11: 0.85 | J11: 9.7 | K11: LOW | L11: N/A | M11: 0.96 | N11: 0.83
A12: TR-0006 | B12: FORREST, TYLEYL | C12: 2026 | D12: 1 | E12: 5.1 | F12: 0.98 | G12: 0.97 | H12: 0.93 | I12: 0.96 | J12: 0.9 | K12: LOW | L12: N/A | M12: 1 | N12: 0.92
